<?xml version="1.0"?>
<robot xmlns:xacro="http://www.ros.org/wiki/xacro">

  <xacro:macro name="wheels">
  
    <!-- Front Left Wheel -->
    <link name="wheel_fl">
      <visual>
        <geometry>
          <cylinder radius="0.05" length="0.03"/>
        </geometry>
        <material name="black">
          <color rgba="0.0 0.0 0.0 1.0"/>
        </material>
      </visual>
      <collision>
        <geometry>
          <cylinder radius="0.05" length="0.03"/>
        </geometry>
      </collision>
      <inertial>
        <mass value="0.5"/>
        <inertia ixx="0.001" ixy="0.0" ixz="0.0"
                 iyy="0.001" iyz="0.0"
                 izz="0.001"/>
      </inertial>
    </link>

    <joint name="wheel_fl_joint" type="continuous">
      <parent link="base_link"/>
      <child link="wheel_fl"/>
      <origin xyz="0.2 0.17 -0.112" rpy="0 1.57 1.57"/>  <!-- Adjusted forward -->
      <axis xyz="0 0 1"/>
    </joint>

    <!-- Front Right Wheel -->
    <link name="wheel_fr">
      <visual>
        <geometry>
          <cylinder radius="0.05" length="0.03"/>
        </geometry>
        <material name="black">
          <color rgba="0.0 0.0 0.0 1.0"/>
        </material>
      </visual>
      <collision>
        <geometry>
          <cylinder radius="0.05" length="0.03"/>
        </geometry>
      </collision>
      <inertial>
        <mass value="0.5"/>
        <inertia ixx="0.001" ixy="0.0" ixz="0.0"
                 iyy="0.001" iyz="0.0"
                 izz="0.001"/>
      </inertial>
    </link>

    <joint name="wheel_fr_joint" type="continuous">
      <parent link="base_link"/>
      <child link="wheel_fr"/>
      <origin xyz="0.2 -0.17 -0.112" rpy="0 1.57 1.57"/>  <!-- Adjusted forward -->
      <axis xyz="0 0 1"/>
    </joint>

    <!-- Rear Left Wheel -->
    <link name="wheel_rl">
      <visual>
        <geometry>
          <cylinder radius="0.05" length="0.03"/>
        </geometry>
        <material name="black">
          <color rgba="0.0 0.0 0.0 1.0"/>
        </material>
      </visual>
      <collision>
        <geometry>
          <cylinder radius="0.05" length="0.03"/>
        </geometry>
      </collision>
      <inertial>
        <mass value="0.5"/>
        <inertia ixx="0.001" ixy="0.0" ixz="0.0"
                 iyy="0.001" iyz="0.0"
                 izz="0.001"/>
      </inertial>
    </link>

    <joint name="wheel_rl_joint" type="continuous">
      <parent link="base_link"/>
      <child link="wheel_rl"/>
      <origin xyz="-0.2 0.17 -0.112" rpy="0 1.57 1.57"/>  <!-- Adjusted backward -->
      <axis xyz="0 0 1"/>
    </joint>

    <!-- Rear Right Wheel -->
    <link name="wheel_rr">
      <visual>
        <geometry>
          <cylinder radius="0.05" length="0.03"/>
        </geometry>
        <material name="black">
          <color rgba="0.0 0.0 0.0 1.0"/>
        </material>
      </visual>
      <collision>
        <geometry>
          <cylinder radius="0.05" length="0.03"/>
        </geometry>
      </collision>
      <inertial>
        <mass value="0.5"/>
        <inertia ixx="0.001" ixy="0.0" ixz="0.0"
                 iyy="0.001" iyz="0.0"
                 izz="0.001"/>
      </inertial>
    </link>

    <joint name="wheel_rr_joint" type="continuous">
      <parent link="base_link"/>
      <child link="wheel_rr"/>
      <origin xyz="-0.2 -0.17 -0.112" rpy="0 1.57 1.57"/>  <!-- Adjusted backward -->
      <axis xyz="0 0 1"/>
    </joint>


  </xacro:macro>

</robot>

